Workbook

Sheet Raw_Data
A1: Order_ID | B1: Order_Date | C1: Brand | D1: Model | E1: Segment | F1: City | G1: Sales_Channel | H1: Payment_Method | I1: Color | J1: Salesperson_ID | K1: Units_Sold | L1: Unit_Price | M1: Discount_Pct | N1: Gross_Sales | O1: Discount_Amount | P1: Net_Sales | Q1: Battery_kWh | R1: Range_km | S1: Customer_Rating | T1: Delivery_Days | U1: Warranty_Years
A2: EV10001 | B2: 46006 | C2: Revolt | D2: RV1 | E2: Premium | F2: Chennai | G2: Online | H2: Finance | I2: Green | J2: SP-002 | K2: 1 | L2: 125898 | M2: 0.08 | N2: 125898 | O2: 10071.84 | P2: 115826.16 | Q2: 3 | R2: 162 | S2: 3.7 | T2: 6 | U2: 5
A3: EV10002 | B3: 45934 | C3: Vida | D3: V2 | E3: Premium | F3: Bengaluru | G3: Fleet | H3: EMI | I3: Red | J3: SP-025 | K3: 2 | L3: 112819 | M3: 0.021 | N3: 225638 | O3: 4738.4 | P3: 220899.6 | Q3: 2 | R3: 116 | S3: 4.4 | T3: 13 | U3: 5
A4: EV10003 | B4: 45964 | C4: TVS | D4: iQube | E4: Premium | F4: Hyderabad | G4: Fleet | H4: EMI | I4: Red | J4: SP-007 | K4: 2 | L4: 125383 | M4: 0.021 | N4: 250766 | O4: 5266.09 | P4: 245499.91 | Q4: 5 | R4: 175 | S4: 4.6 | T4: 11 | U4: 2
A5: EV10004 | B5: 45921 | C5: Bajaj | D5: Chetak Premium | E5: Commuter | F5: Mumbai | G5: Online | H5: Finance | I5: White | J5: SP-030 | K5: 1 | L5: 160095 | M5: 0.046 | N5: 160095 | O5: 7364.37 | P5: 152730.63 | Q5: 4 | R5: 184 | S5: 3.2 | T5: 11 | U5: 3
A6: EV10005 | B6: 46008 | C6: Bajaj | D6: Chetak Urbane | E6: Commuter | F6: Ahmedabad | G6: Online | H6: Cash | I6: Red | J6: SP-028 | K6: 4 | L6: 114286 | M6: 0.04 | N6: 457144 | O6: 18285.76 | P6: 438858.24 | Q6: 2 | R6: 133 | S6: 3.4 | T6: 3 | U6: 5
A7: EV10006 | B7: 45698 | C7: Bajaj | D7: Chetak Premium | E7: Commuter | F7: Ahmedabad | G7: Corporate | H7: EMI | I7: Black | J7: SP-027 | K7: 1 | L7: 144470 | M7: 0.022 | N7: 144470 | O7: 3178.34 | P7: 141291.66 | Q7: 3 | R7: 145 | S7: 3.7 | T7: 12 | U7: 5
A8: EV10007 | B8: 45888 | C8: Hero Electric | D8: Photon | E8: Performance | F8: Ahmedabad | G8: Online | H8: EMI | I8: Blue | J8: SP-001 | K8: 2 | L8: 122830 | M8: 0.105 | N8: 245660 | O8: 25794.3 | P8: 219865.7 | Q8: 3 | R8: 161 | S8: 3.8 | T8: 9 | U8: 2
A9: EV10008 | B9: 45788 | C9: TVS | D9: iQube | E9: Performance | F9: Kolkata | G9: Dealer | H9: Cash | I9: Red | J9: SP-030 | K9: 3 | L9: 127322 | M9: 0.097 | N9: 381966 | O9: 37050.7 | P9: 344915.3 | Q9: 3 | R9: 132 | S9: 4.5 | T9: 11 | U9: 2
A10: EV10009 | B10: 45888 | C10: Hero Electric | D10: Optima | E10: Commuter | F10: Jaipur | G10: Dealer | H10: Finance | I10: Red | J10: SP-028 | K10: 1 | L10: 109806 | M10: 0.043 | N10: 109806 | O10: 4721.66 | P10: 105084.34 | Q10: 2 | R10: 136 | S10: 3.9 | T10: 3 | U10: 3
A11: EV10010 | B11: 45997 | C11: Bajaj | D11: Chetak Urbane | E11: Premium | F11: Jaipur | G11: Fleet | H11: Cash | I11: Black | J11: SP-003 | K11: 4 | L11: 121860 | M11: 0.101 | N11: 487440 | O11: 49231.44 | P11: 438208.56 | Q11: 5 | R11: 191 | S11: 4 | T11: 10 | U11: 5
A12: EV10011 | B12: 45794 | C12: Revolt | D12: RV1 | E12: Commuter | F12: Delhi | G12: Online | H12: Finance | I12: White | J12: SP-003 | K12: 1 | L12: 124432 | M12: 0.047 | N12: 124432 | O12: 5848.3 | P12: 118583.7 | Q12: 3 | R12: 158 | S12: 3.8 | T12: 9 | U12: 2
A13: EV10012 | B13: 45770 | C13: Ather | D13: 450X | E13: Premium | F13: Mumbai | G13: Dealer | H13: Finance | I13: Green | J13: SP-023 | K13: 5 | L13: 141715 | M13: 0.118 | N13: 708575 | O13: 83611.85 | P13: 624963.15 | Q13: 3 | R13: 163 | S13: 4 | T13: 2 | U13: 5
... A23: EV10022 | B23: 45921 | C23: Bajaj | D23: Chetak Premium | E23: Premium | F23: Bengaluru | G23: Dealer | H23: Finance | I23: Green | J23: SP-029 | K23: 2 | L23: 157711 | M23: 0.109 | N23: 315422 | O23: 34381 | P23: 281041 | Q23: 3 | R23: 154 | S23: 4 | T23: 8 | U23: 5
A24: EV10023 | B24: 45715 | C24: Ampere | D24: Primus | E24: Performance | F24: Hyderabad | G24: Online | H24: Cash | I24: Red | J24: SP-030 | K24: 1 | L24: 141784 | M24: 0.102 | N24: 141784 | O24: 14461.97 | P24: 127322.03 | Q24: 3 | R24: 164 | T24: 6 | U24: 2
A25: EV10024 | B25: 45968 | C25: Revolt | D25: RV400 | E25: Performance | F25: Kochi | G25: Dealer | H25: Finance | I25: Grey | J25: SP-030 | K25: 1 | L25: 134201 | M25: 0.117 | N25: 134201 | O25: 15701.52 | P25: 118499.48 | Q25: 4 | R25: 180 | S25: 3.9 | T25: 4 | U25: 3
A26: EV10025 | B26: 45786 | C26: Revolt | D26: RV400 | E26: Commuter | F26: Kolkata | G26: Fleet | H26: EMI | I26: Grey | J26: SP-022 | K26: 1 | L26: 134666 | M26: 0.045 | N26: 134666 | O26: 6059.97 | P26: 128606.03 | Q26: 4 | R26: 193 | S26: 4.7 | T26: 6 | U26: 2
A27: EV10026 | B27: 45733 | C27: Hero Electric | D27: Optima | E27: Premium | F27: Chennai | G27: Corporate | H27: Finance | I27: White | J27: SP-022 | K27: 2 | L27: 101032 | M27: 0.032 | N27: 202064 | O27: 6466.05 | P27: 195597.95 | Q27: 3 | R27: 172 | S27: 4.4 | T27: 5 | U27: 2
A28: EV10027 | B28: 45947 | C28: Hero Electric | D28: Photon | E28: Premium | F28: Delhi | G28: Fleet | H28: EMI | I28: Red | J28: SP-024 | K28: 1 | L28: 108346 | M28: 0.113 | N28: 108346 | O28: 12243.1 | P28: 96102.9 | Q28: 4 | R28: 205 | S28: 4.3 | T28: 9 | U28: 5
A29: EV10028 | B29: 45820 | C29: Bajaj | D29: Chetak Urbane | E29: Commuter | F29: Mumbai | G29: Dealer | H29: EMI | I29: White | J29: SP-003 | K29: 2 | L29: 120498 | M29: 0.075 | N29: 240996 | O29: 18074.7 | P29: 222921.3 | Q29: 5 | R29: 205 | S29: 4.1 | T29: 11 | U29: 5
A30: EV10029 | B30: 45747 | C30: Revolt | D30: RV400 | E30: Commuter | F30: Ahmedabad | G30: Fleet | H30: Cash | I30: Grey | J30: SP-029 | K30: 1 | L30: 148159 | M30: 0.022 | N30: 148159 | O30: 3259.5 | P30: 144899.5 | Q30: 4 | R30: 174 | S30: 3.9 | T30: 6 | U30: 3
A31: EV10030 | B31: 46014 | C31: Ather | D31: 450S | E31: Premium | F31: Chennai | G31: Fleet | H31: Cash | I31: Grey | J31: SP-023 | K31: 3 | L31: 136884 | M31: 0.119 | N31: 410652 | O31: 48867.59 | P31: 361784.41 | Q31: 3 | R31: 179 | S31: 3.8 | T31: 9 | U31: 5
A32: EV10031 | B32: 46018 | C32: Ather | D32: Rizta | E32: Commuter | F32: Bengaluru | G32: Fleet | H32: Cash | I32: Red | J32: SP-014 | K32: 1 | L32: 136998 | M32: 0.07 | N32: 136998 | O32: 9589.86 | P32: 127408.14 | Q32: 3 | R32: 156 | S32: 4 | T32: 5 | U32: 2
A33: EV10032 | B33: 45709 | C33: Revolt | D33: RV1 | E33: Performance | F33: Jaipur | G33: Corporate | H33: Cash | I33: Grey | J33: SP-010 | K33: 2 | L33: 123414 | M33: 0.065 | N33: 246828 | O33: 16043.82 | P33: 230784.18 | Q33: 3 | R33: 178 | S33: 3.6 | T33: 5 | U33: 2
A34: EV10033 | B34: 45880 | C34: Ola Electric | D34: S1 X | E34: Premium | F34: Ahmedabad | G34: Online | H34: Cash | I34: White | J34: SP-027 | K34: 1 | L34: 109534 | M34: 0.075 | N34: 109534 | O34: 8215.05 | P34: 101318.95 | Q34: 4 | R34: 183 | S34: 4.1 | T34: 7 | U34: 5
A35: EV10034 | B35: 45662 | C35: Ola Electric | D35: S1 Air | E35: Commuter | F35: Hyderabad | G35: Fleet | H35: Finance | I35: Red | J35: SP-019 | K35: 2 | L35: 111854 | M35: 0.078 | N35: 223708 | O35: 17449.22 | P35: 206258.78 | Q35: 5 | R35: 196 | S35: 4.3 | T35: 8 | U35: 2
A36: EV10035 | B36: 45839 | C36: Hero Electric | D36: Photon | E36: Performance | F36: Jaipur | G36: Corporate | H36: Cash | I36: Blue | J36: SP-013 | K36: 2 | L36: 112104 | M36: 0.053 | N36: 224208 | O36: 11883.02 | P36: 212324.98 | Q36: 3 | R36: 157 | S36: 3.4 | T36: 11 | U36: 2
... A97: EV10096 | B97: 46001 | C97: Hero Electric | D97: Optima | E97: Commuter | F97: Jaipur | G97: Dealer | H97: Finance | I97: Black | J97: SP-008 | K97: 1 | L97: 113169 | M97: 0.035 | N97: 113169 | O97: 3960.92 | P97: 109208.08 | Q97: 3 | R97: 152 | S97: 4.8 | T97: 7 | U97: 5
A98: EV10097 | B98: 45836 | C98: TVS | D98: X | E98: Premium | F98: Ahmedabad | G98: Fleet | H98: Finance | I98: Red | J98: SP-001 | K98: 1 | L98: 175299 | M98: 0.119 | N98: 175299 | O98: 20860.58 | P98: 154438.42 | Q98: 3 | R98: 192 | T98: 5 | U98: 2
A99: EV10098 | B99: 45946 | C99: ola electric | D99: S1 Pro | E99: Performance | F99: Delhi | G99: Fleet | H99: EMI | I99: Grey | J99: SP-003 | K99: 4 | L99: 133217 | M99: 0.102 | N99: 532868 | O99: 54352.54 | P99: 478515.46 | Q99: 3 | R99: 171 | S99: 3.7 | T99: 3 | U99: 3
A100: EV10099 | B100: 45666 | C100: TVS | D100: X | E100: Performance | F100: Kolkata | G100: Corporate | H100: Finance | I100: White | J100: SP-022 | K100: 5 | L100: 170509 | M100: 0.074 | N100: 852545 | O100: 63088.33 | P100: 789456.67 | Q100: 4 | R100: 186 | S100: 4.4 | T100: 5 | U100: 3
A101: EV10100 | B101: 45660 | C101: Ola Electric | D101: S1 X | E101: Performance | F101: Kochi | G101: Corporate | H101: EMI | I101: Green | J101: SP-004 | K101: 1 | L101: 101110 | M101: 0.064 | N101: 101110 | O101: 6471.04 | P101: 94638.96 | Q101: 4 | R101: 202 | S101: 4.6 | T101: 10 | U101: 2
A102: EV10101 | B102: 45878 | C102: Hero Electric | D102: Photon | E102: Performance | F102: Bengaluru | G102: Fleet | H102: Finance | I102: Blue | J102: SP-003 | K102: 3 | L102: 118705 | M102: 0.07 | N102: 356115 | O102: 24928.05 | P102: 331186.95 | Q102: 4 | R102: 170 | S102: 4.4 | T102: 9 | U102: 2
A103: EV10102 | B103: 45864 | C103: Hero Electric | D103: Optima | E103: Premium | F103: Delhi | G103: Corporate | H103: Cash | I103: Red | J103: SP-026 | K103: 1 | L103: 105500 | M103: 0.107 | N103: 105500 | O103: 11288.5 | P103: 94211.5 | Q103: 4 | R103: 176 | S103: 4.8 | T103: 5 | U103: 3
A104: EV10103 | B104: 45885 | C104: Hero Electric | D104: Photon | E104: Commuter | F104: Mumbai | G104: Fleet | H104: Cash | I104: Black | J104: SP-003 | K104: 4 | L104: 122601 | M104: 0.062 | N104: 490404 | O104: 30405.05 | P104: 459998.95 | Q104: 3 | R104: 173 | S104: 4.2 | T104: 13 | U104: 5
A105: EV10104 | B105: 45744 | C105: Ola Electric | D105: S1 Air | E105: Performance | F105: Ahmedabad | G105: Corporate | H105: Cash | I105: Red | J105: SP-002 | K105: 2 | L105: 114102 | M105: 0.071 | N105: 228204 | O105: 16202.48 | P105: 212001.52 | Q105: 3 | R105: 162 | S105: 3.8 | T105: 7 | U105: 2
A106: EV10105 | B106: 45802 | C106: Revolt | D106: RV1 | E106: Performance | F106: Kochi | G106: Corporate | H106: Finance | I106: Green | J106: SP-016 | K106: 1 | L106: 129086 | M106: 0.046 | N106: 129086 | O106: 5937.96 | P106: 123148.04 | Q106: 4 | R106: 195 | S106: 3.8 | T106: 9 | U106: 2
A107: EV10106 | B107: 45923 | C107: Ola Electric | D107: S1 Pro | E107: Performance | F107: Chennai | G107: Fleet | H107: Cash | I107: Black | J107: SP-017 | K107: 2 | L107: 134456 | M107: 0.065 | N107: 268912 | O107: 17479.28 | P107: 251432.72 | Q107: 4 | R107: 166 | S107: 3.4 | T107: 12 | U107: 2
A108: EV10107 | B108: 45969 | C108: Vida | D108: V2 | E108: Commuter | F108: Delhi | G108: Corporate | H108: EMI | I108: Green | J108: SP-005 | K108: 2 | L108: 116771 | M108: 0.041 | N108: 233542 | O108: 9575.22 | P108: 223966.78 | Q108: 2 | R108: 145 | S108: 4.1 | T108: 6 | U108: 3
A109: EV10108 | B109: 45982 | C109: Hero Electric | D109: Optima | E109: Premium | F109: Jaipur | G109: Corporate | H109: EMI | I109: Blue | J109: SP-018 | K109: 1 | L109: 107294 | M109: 0.089 | N109: 107294 | O109: 9549.17 | P109: 97744.83 | Q109: 3 | R109: 187 | S109: 4 | T109: 3 | U109: 2
...

Sheet Cleaned Data
A1: Order_ID | B1: Order_Date | C1: Brand | D1: Model | E1: Segment | F1: City | G1: Sales_Channel | H1: Payment_Method | I1: Payment M | J1: Color | K1: Salesperson_ID | L1: Units_Sold | M1: Unit_Price | N1: Discount_Pct | O1: Cleaned Dis% | P1: Gross_Sales | Q1: Discount_Amount | R1: Net_Sales | S1: Battery_kWh | T1: Range_km | U1: Customer_Rating | V1: Delivery_Days | W1: Cleaned Delivery Days | X1: Warranty_Years | Y1: ASP | Z1: Month-Year | AA1: Month | AB1: Quarter
A2: EV10001 | B2: 46006 | C2: Revolt | D2: RV1 | E2: Premium | F2: Chennai | G2: Online | H2: Finance | I2: =IF('Cleaned Data'!H2="Emi","EMI",'Cleaned Data'!H2) -> Finance | J2: Green | K2: SP-002 | L2: 1 | M2: 125898 | N2: 0.08 | O2: =IF(TRIM(N2&"")="","missing",N2) -> 0.08 | P2: 125898 | Q2: 10071.84 | R2: 115826.16 | S2: 3 | T2: 162 | U2: 3.7 | V2: 6 | W2: =IF('Cleaned Data'!V2<0,"Review",'Cleaned Data'!V2) -> 6 | X2: 5 | Y2: =IFERROR('Cleaned Data'!R2/'Cleaned Data'!L2,0) -> 115826.16 | Z2: =TEXT(EV_Sales[[#This Row],[Order_Date]],"mmm-yyyy") -> Dec-2025 | AA2: =MONTH(EV_Sales[[#This Row],[Order_Date]]) -> 12 | AB2: ="Q"&ROUNDUP(MONTH(EV_Sales[[#This Row],[Order_Date]])/3,0) -> Q4
A3: EV10002 | B3: 45934 | C3: Vida | D3: V2 | E3: Premium | F3: Bengaluru | G3: Fleet | H3: Emi | I3: =IF('Cleaned Data'!H3="Emi","EMI",'Cleaned Data'!H3) -> EMI | J3: Red | K3: SP-025 | L3: 2 | M3: 112819 | N3: 0.021 | O3: =IF(TRIM(N3&"")="","missing",N3) -> 0.021 | P3: 225638 | Q3: 4738.4 | R3: 220899.6 | S3: 2 | T3: 116 | U3: 4.4 | V3: 13 | W3: =IF('Cleaned Data'!V3<0,"Review",'Cleaned Data'!V3) -> 13 | X3: 5 | Y3: =IFERROR('Cleaned Data'!R3/'Cleaned Data'!L3,0) -> 110449.8 | Z3: =TEXT(EV_Sales[[#This Row],[Order_Date]],"mmm-yyyy") -> Oct-2025 | AA3: =MONTH(EV_Sales[[#This Row],[Order_Date]]) -> 10 | AB3: ="Q"&ROUNDUP(MONTH(EV_Sales[[#This Row],[Order_Date]])/3,0) -> Q4
A4: EV10003 | B4: 45964 | C4: TVS | D4: iQube | E4: Premium | F4: Hyderabad | G4: Fleet | H4: Emi | I4: =IF('Cleaned Data'!H4="Emi","EMI",'Cleaned Data'!H4) -> EMI | J4: Red | K4: SP-007 | L4: 2 | M4: 125383 | N4: 0.021 | O4: =IF(TRIM(N4&"")="","missing",N4) -> 0.021 | P4: 250766 | Q4: 5266.09 | R4: 245499.91 | S4: 5 | T4: 175 | U4: 4.6 | V4: 11 | W4: =IF('Cleaned Data'!V4<0,"Review",'Cleaned Data'!V4) -> 11 | X4: 2 | Y4: =IFERROR('Cleaned Data'!R4/'Cleaned Data'!L4,0) -> 122749.96 | Z4: =TEXT(EV_Sales[[#This Row],[Order_Date]],"mmm-yyyy") -> Nov-2025 | AA4: =MONTH(EV_Sales[[#This Row],[Order_Date]]) -> 11 | AB4: ="Q"&ROUNDUP(MONTH(EV_Sales[[#This Row],[Order_Date]])/3,0) -> Q4
A5: EV10004 | B5: 45921 | C5: Bajaj | D5: Chetak Premium | E5: Commuter | F5: Mumbai | G5: Online | H5: Finance | I5: =IF('Cleaned Data'!H5="Emi","EMI",'Cleaned Data'!H5) -> Finance | J5: White | K5: SP-030 | L5: 1 | M5: 160095 | N5: 0.046 | O5: =IF(TRIM(N5&"")="","missing",N5) -> 0.046 | P5: 160095 | Q5: 7364.37 | R5: 152730.63 | S5: 4 | T5: 184 | U5: 3.2 | V5: 11 | W5: =IF('Cleaned Data'!V5<0,"Review",'Cleaned Data'!V5) -> 11 | X5: 3 | Y5: =IFERROR('Cleaned Data'!R5/'Cleaned Data'!L5,0) -> 152730.63 | Z5: =TEXT(EV_Sales[[#This Row],[Order_Date]],"mmm-yyyy") -> Sep-2025 | AA5: =MONTH(EV_Sales[[#This Row],[Order_Date]]) -> 9 | AB5: ="Q"&ROUNDUP(MONTH(EV_Sales[[#This Row],[Order_Date]])/3,0) -> Q3
A6: EV10005 | B6: 46008 | C6: Bajaj | D6: Chetak Urbane | E6: Commuter | F6: Ahmedabad | G6: Online | H6: Cash | I6: =IF('Cleaned Data'!H6="Emi","EMI",'Cleaned Data'!H6) -> Cash | J6: Red | K6: SP-028 | L6: 4 | M6: 114286 | N6: 0.04 | O6: =IF(TRIM(N6&"")="","missing",N6) -> 0.04 | P6: 457144 | Q6: 18285.76 | R6: 438858.24 | S6: 2 | T6: 133 | U6: 3.4 | V6: 3 | W6: =IF('Cleaned Data'!V6<0,"Review",'Cleaned Data'!V6) -> 3 | X6: 5 | Y6: =IFERROR('Cleaned Data'!R6/'Cleaned Data'!L6,0) -> 109714.56 | Z6: =TEXT(EV_Sales[[#This Row],[Order_Date]],"mmm-yyyy") -> Dec-2025 | AA6: =MONTH(EV_Sales[[#This Row],[Order_Date]]) -> 12 | AB6: ="Q"&ROUNDUP(MONTH(EV_Sales[[#This Row],[Order_Date]])/3,0) -> Q4
A7: EV10006 | B7: 45698 | C7: Bajaj | D7: Chetak Premium | E7: Commuter | F7: Ahmedabad | G7: Corporate | H7: Emi | I7: =IF('Cleaned Data'!H7="Emi","EMI",'Cleaned Data'!H7) -> EMI | J7: Black | K7: SP-027 | L7: 1 | M7: 144470 | N7: 0.022 | O7: =IF(TRIM(N7&"")="","missing",N7) -> 0.022 | P7: 144470 | Q7: 3178.34 | R7: 141291.66 | S7: 3 | T7: 145 | U7: 3.7 | V7: 12 | W7: =IF('Cleaned Data'!V7<0,"Review",'Cleaned Data'!V7) -> 12 | X7: 5 | Y7: =IFERROR('Cleaned Data'!R7/'Cleaned Data'!L7,0) -> 141291.66 | Z7: =TEXT(EV_Sales[[#This Row],[Order_Date]],"mmm-yyyy") -> Feb-2025 | AA7: =MONTH(EV_Sales[[#This Row],[Order_Date]]) -> 2 | AB7: ="Q"&ROUNDUP(MONTH(EV_Sales[[#This Row],[Order_Date]])/3,0) -> Q1
A8: EV10007 | B8: 45888 | C8: Hero Electric | D8: Photon | E8: Performance | F8: Ahmedabad | G8: Online | H8: Emi | I8: =IF('Cleaned Data'!H8="Emi","EMI",'Cleaned Data'!H8) -> EMI | J8: Blue | K8: SP-001 | L8: 2 | M8: 122830 | N8: 0.105 | O8: =IF(TRIM(N8&"")="","missing",N8) -> 0.105 | P8: 245660 | Q8: 25794.3 | R8: 219865.7 | S8: 3 | T8: 161 | U8: 3.8 | V8: 9 | W8: =IF('Cleaned Data'!V8<0,"Review",'Cleaned Data'!V8) -> 9 | X8: 2 | Y8: =IFERROR('Cleaned Data'!R8/'Cleaned Data'!L8,0) -> 109932.85 | Z8: =TEXT(EV_Sales[[#This Row],[Order_Date]],"mmm-yyyy") -> Aug-2025 | AA8: =MONTH(EV_Sales[[#This Row],[Order_Date]]) -> 8 | AB8: ="Q"&ROUNDUP(MONTH(EV_Sales[[#This Row],[Order_Date]])/3,0) -> Q3
A9: EV10008 | B9: 45788 | C9: TVS | D9: iQube | E9: Performance | F9: Kolkata | G9: Dealer | H9: Cash | I9: =IF('Cleaned Data'!H9="Emi","EMI",'Cleaned Data'!H9) -> Cash | J9: Red | K9: SP-030 | L9: 3 | M9: 127322 | N9: 0.097 | O9: =IF(TRIM(N9&"")="","missing",N9) -> 0.097 | P9: 381966 | Q9: 37050.7 | R9: 344915.3 | S9: 3 | T9: 132 | U9: 4.5 | V9: 11 | W9: =IF('Cleaned Data'!V9<0,"Review",'Cleaned Data'!V9) -> 11 | X9: 2 | Y9: =IFERROR('Cleaned Data'!R9/'Cleaned Data'!L9,0) -> 114971.77 | Z9: =TEXT(EV_Sales[[#This Row],[Order_Date]],"mmm-yyyy") -> May-2025 | AA9: =MONTH(EV_Sales[[#This Row],[Order_Date]]) -> 5 | AB9: ="Q"&ROUNDUP(MONTH(EV_Sales[[#This Row],[Order_Date]])/3,0) -> Q2
A10: EV10009 | B10: 45888 | C10: Hero Electric | D10: Optima | E10: Commuter | F10: Jaipur | G10: Dealer | H10: Finance | I10: =IF('Cleaned Data'!H10="Emi","EMI",'Cleaned Data'!H10) -> Finance | J10: Red | K10: SP-028 | L10: 1 | M10: 109806 | N10: 0.043 | O10: =IF(TRIM(N10&"")="","missing",N10) -> 0.043 | P10: 109806 | Q10: 4721.66 | R10: 105084.34 | S10: 2 | T10: 136 | U10: 3.9 | V10: 3 | W10: =IF('Cleaned Data'!V10<0,"Review",'Cleaned Data'!V10) -> 3 | X10: 3 | Y10: =IFERROR('Cleaned Data'!R10/'Cleaned Data'!L10,0) -> 105084.34 | Z10: =TEXT(EV_Sales[[#This Row],[Order_Date]],"mmm-yyyy") -> Aug-2025 | AA10: =MONTH(EV_Sales[[#This Row],[Order_Date]]) -> 8 | AB10: ="Q"&ROUNDUP(MONTH(EV_Sales[[#This Row],[Order_Date]])/3,0) -> Q3
A11: EV10010 | B11: 45997 | C11: Bajaj | D11: Chetak Urbane | E11: Premium | F11: Jaipur | G11: Fleet | H11: Cash | I11: =IF('Cleaned Data'!H11="Emi","EMI",'Cleaned Data'!H11) -> Cash | J11: Black | K11: SP-003 | L11: 4 | M11: 121860 | N11: 0.101 | O11: =IF(TRIM(N11&"")="","missing",N11) -> 0.101 | P11: 487440 | Q11: 49231.44 | R11: 438208.56 | S11: 5 | T11: 191 | U11: 4 | V11: 10 | W11: =IF('Cleaned Data'!V11<0,"Review",'Cleaned Data'!V11) -> 10 | X11: 5 | Y11: =IFERROR('Cleaned Data'!R11/'Cleaned Data'!L11,0) -> 109552.14 | Z11: =TEXT(EV_Sales[[#This Row],[Order_Date]],"mmm-yyyy") -> Dec-2025 | AA11: =MONTH(EV_Sales[[#This Row],[Order_Date]]) -> 12 | AB11: ="Q"&ROUNDUP(MONTH(EV_Sales[[#This Row],[Order_Date]])/3,0) -> Q4
A12: EV10011 | B12: 45794 | C12: Revolt | D12: RV1 | E12: Commuter | F12: Delhi | G12: Online | H12: Finance | I12: =IF('Cleaned Data'!H12="Emi","EMI",'Cleaned Data'!H12) -> Finance | J12: White | K12: SP-003 | L12: 1 | M12: 124432 | N12: 0.047 | O12: =IF(TRIM(N12&"")="","missing",N12) -> 0.047 | P12: 124432 | Q12: 5848.3 | R12: 118583.7 | S12: 3 | T12: 158 | U12: 3.8 | V12: 9 | W12: =IF('Cleaned Data'!V12<0,"Review",'Cleaned Data'!V12) -> 9 | X12: 2 | Y12: =IFERROR('Cleaned Data'!R12/'Cleaned Data'!L12,0) -> 118583.7 | Z12: =TEXT(EV_Sales[[#This Row],[Order_Date]],"mmm-yyyy") -> May-2025 | AA12: =MONTH(EV_Sales[[#This Row],[Order_Date]]) -> 5 | AB12: ="Q"&ROUNDUP(MONTH(EV_Sales[[#This Row],[Order_Date]])/3,0) -> Q2
A13: EV10012 | B13: 45770 | C13: Ather | D13: 450X | E13: Premium | F13: Mumbai | G13: Dealer | H13: Finance | I13: =IF('Cleaned Data'!H13="Emi","EMI",'Cleaned Data'!H13) -> Finance | J13: Green | K13: SP-023 | L13: 5 | M13: 141715 | N13: 0.118 | O13: =IF(TRIM(N13&"")="","missing",N13) -> 0.118 | P13: 708575 | Q13: 83611.85 | R13: 624963.15 | S13: 3 | T13: 163 | U13: 4 | V13: 2 | W13: =IF('Cleaned Data'!V13<0,"Review",'Cleaned Data'!V13) -> 2 | X13: 5 | Y13: =IFERROR('Cleaned Data'!R13/'Cleaned Data'!L13,0) -> 124992.63 | Z13: =TEXT(EV_Sales[[#This Row],[Order_Date]],"mmm-yyyy") -> Apr-2025 | AA13: =MONTH(EV_Sales[[#This Row],[Order_Date]]) -> 4 | AB13: ="Q"&ROUNDUP(MONTH(EV_Sales[[#This Row],[Order_Date]])/3,0) -> Q2
... A23: EV10022 | B23: 45921 | C23: Bajaj | D23: Chetak Premium | E23: Premium | F23: Bengaluru | G23: Dealer | H23: Finance | I23: =IF('Cleaned Data'!H23="Emi","EMI",'Cleaned Data'!H23) -> Finance | J23: Green | K23: SP-029 | L23: 2 | M23: 157711 | N23: 0.109 | O23: =IF(TRIM(N23&"")="","missing",N23) -> 0.109 | P23: 315422 | Q23: 34381 | R23: 281041 | S23: 3 | T23: 154 | U23: 4 | V23: 8 | W23: =IF('Cleaned Data'!V23<0,"Review",'Cleaned Data'!V23) -> 8 | X23: 5 | Y23: =IFERROR('Cleaned Data'!R23/'Cleaned Data'!L23,0) -> 140520.5 | Z23: =TEXT(EV_Sales[[#This Row],[Order_Date]],"mmm-yyyy") -> Sep-2025 | AA23: =MONTH(EV_Sales[[#This Row],[Order_Date]]) -> 9 | AB23: ="Q"&ROUNDUP(MONTH(EV_Sales[[#This Row],[Order_Date]])/3,0) -> Q3
A24: EV10023 | B24: 45715 | C24: Ampere | D24: Primus | E24: Performance | F24: Hyderabad | G24: Online | H24: Cash | I24: =IF('Cleaned Data'!H24="Emi","EMI",'Cleaned Data'!H24) -> Cash | J24: Red | K24: SP-030 | L24: 1 | M24: 141784 | N24: 0.102 | O24: =IF(TRIM(N24&"")="","missing",N24) -> 0.102 | P24: 141784 | Q24: 14461.97 | R24: 127322.03 | S24: 3 | T24: 164 | U24: Missing | V24: 6 | W24: =IF('Cleaned Data'!V24<0,"Review",'Cleaned Data'!V24) -> 6 | X24: 2 | Y24: =IFERROR('Cleaned Data'!R24/'Cleaned Data'!L24,0) -> 127322.03 | Z24: =TEXT(EV_Sales[[#This Row],[Order_Date]],"mmm-yyyy") -> Feb-2025 | AA24: =MONTH(EV_Sales[[#This Row],[Order_Date]]) -> 2 | AB24: ="Q"&ROUNDUP(MONTH(EV_Sales[[#This Row],[Order_Date]])/3,0) -> Q1
A25: EV10024 | B25: 45968 | C25: Revolt | D25: RV400 | E25: Performance | F25: Kochi | G25: Dealer | H25: Finance | I25: =IF('Cleaned Data'!H25="Emi","EMI",'Cleaned Data'!H25) -> Finance | J25: Grey | K25: SP-030 | L25: 1 | M25: 134201 | N25: 0.117 | O25: =IF(TRIM(N25&"")="","missing",N25) -> 0.117 | P25: 134201 | Q25: 15701.52 | R25: 118499.48 | S25: 4 | T25: 180 | U25: 3.9 | V25: 4 | W25: =IF('Cleaned Data'!V25<0,"Review",'Cleaned Data'!V25) -> 4 | X25: 3 | Y25: =IFERROR('Cleaned Data'!R25/'Cleaned Data'!L25,0) -> 118499.48 | Z25: =TEXT(EV_Sales[[#This Row],[Order_Date]],"mmm-yyyy") -> Nov-2025 | AA25: =MONTH(EV_Sales[[#This Row],[Order_Date]]) -> 11 | AB25: ="Q"&ROUNDUP(MONTH(EV_Sales[[#This Row],[Order_Date]])/3,0) -> Q4
A26: EV10025 | B26: 45786 | C26: Revolt | D26: RV400 | E26: Commuter | F26: Kolkata | G26: Fleet | H26: Emi | I26: =IF('Cleaned Data'!H26="Emi","EMI",'Cleaned Data'!H26) -> EMI | J26: Grey | K26: SP-022 | L26: 1 | M26: 134666 | N26: 0.045 | O26: =IF(TRIM(N26&"")="","missing",N26) -> 0.045 | P26: 134666 | Q26: 6059.97 | R26: 128606.03 | S26: 4 | T26: 193 | U26: 4.7 | V26: 6 | W26: =IF('Cleaned Data'!V26<0,"Review",'Cleaned Data'!V26) -> 6 | X26: 2 | Y26: =IFERROR('Cleaned Data'!R26/'Cleaned Data'!L26,0) -> 128606.03 | Z26: =TEXT(EV_Sales[[#This Row],[Order_Date]],"mmm-yyyy") -> May-2025 | AA26: =MONTH(EV_Sales[[#This Row],[Order_Date]]) -> 5 | AB26: ="Q"&ROUNDUP(MONTH(EV_Sales[[#This Row],[Order_Date]])/3,0) -> Q2
A27: EV10026 | B27: 45733 | C27: Hero Electric | D27: Optima | E27: Premium | F27: Chennai | G27: Corporate | H27: Finance | I27: =IF('Cleaned Data'!H27="Emi","EMI",'Cleaned Data'!H27) -> Finance | J27: White | K27: SP-022 | L27: 2 | M27: 101032 | N27: 0.032 | O27: =IF(TRIM(N27&"")="","missing",N27) -> 0.032 | P27: 202064 | Q27: 6466.05 | R27: 195597.95 | S27: 3 | T27: 172 | U27: 4.4 | V27: 5 | W27: =IF('Cleaned Data'!V27<0,"Review",'Cleaned Data'!V27) -> 5 | X27: 2 | Y27: =IFERROR('Cleaned Data'!R27/'Cleaned Data'!L27,0) -> 97798.975 | Z27: =TEXT(EV_Sales[[#This Row],[Order_Date]],"mmm-yyyy") -> Mar-2025 | AA27: =MONTH(EV_Sales[[#This Row],[Order_Date]]) -> 3 | AB27: ="Q"&ROUNDUP(MONTH(EV_Sales[[#This Row],[Order_Date]])/3,0) -> Q1
A28: EV10027 | B28: 45947 | C28: Hero Electric | D28: Photon | E28: Premium | F28: Delhi | G28: Fleet | H28: Emi | I28: =IF('Cleaned Data'!H28="Emi","EMI",'Cleaned Data'!H28) -> EMI | J28: Red | K28: SP-024 | L28: 1 | M28: 108346 | N28: 0.113 | O28: =IF(TRIM(N28&"")="","missing",N28) -> 0.113 | P28: 108346 | Q28: 12243.1 | R28: 96102.9 | S28: 4 | T28: 205 | U28: 4.3 | V28: 9 | W28: =IF('Cleaned Data'!V28<0,"Review",'Cleaned Data'!V28) -> 9 | X28: 5 | Y28: =IFERROR('Cleaned Data'!R28/'Cleaned Data'!L28,0) -> 96102.9 | Z28: =TEXT(EV_Sales[[#This Row],[Order_Date]],"mmm-yyyy") -> Oct-2025 | AA28: =MONTH(EV_Sales[[#This Row],[Order_Date]]) -> 10 | AB28: ="Q"&ROUNDUP(MONTH(EV_Sales[[#This Row],[Order_Date]])/3,0) -> Q4
A29: EV10028 | B29: 45820 | C29: Bajaj | D29: Chetak Urbane | E29: Commuter | F29: Mumbai | G29: Dealer | H29: Emi | I29: =IF('Cleaned Data'!H29="Emi","EMI",'Cleaned Data'!H29) -> EMI | J29: White | K29: SP-003 | L29: 2 | M29: 120498 | N29: 0.075 | O29: =IF(TRIM(N29&"")="","missing",N29) -> 0.075 | P29: 240996 | Q29: 18074.7 | R29: 222921.3 | S29: 5 | T29: 205 | U29: 4.1 | V29: 11 | W29: =IF('Cleaned Data'!V29<0,"Review",'Cleaned Data'!V29) -> 11 | X29: 5 | Y29: =IFERROR('Cleaned Data'!R29/'Cleaned Data'!L29,0) -> 111460.65 | Z29: =TEXT(EV_Sales[[#This Row],[Order_Date]],"mmm-yyyy") -> Jun-2025 | AA29: =MONTH(EV_Sales[[#This Row],[Order_Date]]) -> 6 | AB29: ="Q"&ROUNDUP(MONTH(EV_Sales[[#This Row],[Order_Date]])/3,0) -> Q2
A30: EV10029 | B30: 45747 | C30: Revolt | D30: RV400 | E30: Commuter | F30: Ahmedabad | G30: Fleet | H30: Cash | I30: =IF('Cleaned Data'!H30="Emi","EMI",'Cleaned Data'!H30) -> Cash | J30: Grey | K30: SP-029 | L30: 1 | M30: 148159 | N30: 0.022 | O30: =IF(TRIM(N30&"")="","missing",N30) -> 0.022 | P30: 148159 | Q30: 3259.5 | R30: 144899.5 | S30: 4 | T30: 174 | U30: 3.9 | V30: 6 | W30: =IF('Cleaned Data'!V30<0,"Review",'Cleaned Data'!V30) -> 6 | X30: 3 | Y30: =IFERROR('Cleaned Data'!R30/'Cleaned Data'!L30,0) -> 144899.5 | Z30: =TEXT(EV_Sales[[#This Row],[Order_Date]],"mmm-yyyy") -> Mar-2025 | AA30: =MONTH(EV_Sales[[#This Row],[Order_Date]]) -> 3 | AB30: ="Q"&ROUNDUP(MONTH(EV_Sales[[#This Row],[Order_Date]])/3,0) -> Q1
A31: EV10030 | B31: 46014 | C31: Ather | D31: 450S | E31: Premium | F31: Chennai | G31: Fleet | H31: Cash | I31: =IF('Cleaned Data'!H31="Emi","EMI",'Cleaned Data'!H31) -> Cash | J31: Grey | K31: SP-023 | L31: 3 | M31: 136884 | N31: 0.119 | O31: =IF(TRIM(N31&"")="","missing",N31) -> 0.119 | P31: 410652 | Q31: 48867.59 | R31: 361784.41 | S31: 3 | T31: 179 | U31: 3.8 | V31: 9 | W31: =IF('Cleaned Data'!V31<0,"Review",'Cleaned Data'!V31) -> 9 | X31: 5 | Y31: =IFERROR('Cleaned Data'!R31/'Cleaned Data'!L31,0) -> 120594.8 | Z31: =TEXT(EV_Sales[[#This Row],[Order_Date]],"mmm-yyyy") -> Dec-2025 | AA31: =MONTH(EV_Sales[[#This Row],[Order_Date]]) -> 12 | AB31: ="Q"&ROUNDUP(MONTH(EV_Sales[[#This Row],[Order_Date]])/3,0) -> Q4
A32: EV10031 | B32: 46018 | C32: Ather | D32: Rizta | E32: Commuter | F32: Bengaluru | G32: Fleet | H32: Cash | I32: =IF('Cleaned Data'!H32="Emi","EMI",'Cleaned Data'!H32) -> Cash | J32: Red | K32: SP-014 | L32: 1 | M32: 136998 | N32: 0.07 | O32: =IF(TRIM(N32&"")="","missing",N32) -> 0.07 | P32: 136998 | Q32: 9589.86 | R32: 127408.14 | S32: 3 | T32: 156 | U32: 4 | V32: 5 | W32: =IF('Cleaned Data'!V32<0,"Review",'Cleaned Data'!V32) -> 5 | X32: 2 | Y32: =IFERROR('Cleaned Data'!R32/'Cleaned Data'!L32,0) -> 127408.14 | Z32: =TEXT(EV_Sales[[#This Row],[Order_Date]],"mmm-yyyy") -> Dec-2025 | AA32: =MONTH(EV_Sales[[#This Row],[Order_Date]]) -> 12 | AB32: ="Q"&ROUNDUP(MONTH(EV_Sales[[#This Row],[Order_Date]])/3,0) -> Q4
A33: EV10032 | B33: 45709 | C33: Revolt | D33: RV1 | E33: Performance | F33: Jaipur | G33: Corporate | H33: Cash | I33: =IF('Cleaned Data'!H33="Emi","EMI",'Cleaned Data'!H33) -> Cash | J33: Grey | K33: SP-010 | L33: 2 | M33: 123414 | N33: 0.065 | O33: =IF(TRIM(N33&"")="","missing",N33) -> 0.065 | P33: 246828 | Q33: 16043.82 | R33: 230784.18 | S33: 3 | T33: 178 | U33: 3.6 | V33: 5 | W33: =IF('Cleaned Data'!V33<0,"Review",'Cleaned Data'!V33) -> 5 | X33: 2 | Y33: =IFERROR('Cleaned Data'!R33/'Cleaned Data'!L33,0) -> 115392.09 | Z33: =TEXT(EV_Sales[[#This Row],[Order_Date]],"mmm-yyyy") -> Feb-2025 | AA33: =MONTH(EV_Sales[[#This Row],[Order_Date]]) -> 2 | AB33: ="Q"&ROUNDUP(MONTH(EV_Sales[[#This Row],[Order_Date]])/3,0) -> Q1
A34: EV10033 | B34: 45880 | C34: Ola Electric | D34: S1 X | E34: Premium | F34: Ahmedabad | G34: Online | H34: Cash | I34: =IF('Cleaned Data'!H34="Emi","EMI",'Cleaned Data'!H34) -> Cash | J34: White | K34: SP-027 | L34: 1 | M34: 109534 | N34: 0.075 | O34: =IF(TRIM(N34&"")="","missing",N34) -> 0.075 | P34: 109534 | Q34: 8215.05 | R34: 101318.95 | S34: 4 | T34: 183 | U34: 4.1 | V34: 7 | W34: =IF('Cleaned Data'!V34<0,"Review",'Cleaned Data'!V34) -> 7 | X34: 5 | Y34: =IFERROR('Cleaned Data'!R34/'Cleaned Data'!L34,0) -> 101318.95 | Z34: =TEXT(EV_Sales[[#This Row],[Order_Date]],"mmm-yyyy") -> Aug-2025 | AA34: =MONTH(EV_Sales[[#This Row],[Order_Date]]) -> 8 | AB34: ="Q"&ROUNDUP(MONTH(EV_Sales[[#This Row],[Order_Date]])/3,0) -> Q3
A35: EV10034 | B35: 45662 | C35: Ola Electric | D35: S1 Air | E35: Commuter | F35: Hyderabad | G35: Fleet | H35: Finance | I35: =IF('Cleaned Data'!H35="Emi","EMI",'Cleaned Data'!H35) -> Finance | J35: Red | K35: SP-019 | L35: 2 | M35: 111854 | N35: 0.078 | O35: =IF(TRIM(N35&"")="","missing",N35) -> 0.078 | P35: 223708 | Q35: 17449.22 | R35: 206258.78 | S35: 5 | T35: 196 | U35: 4.3 | V35: 8 | W35: =IF('Cleaned Data'!V35<0,"Review",'Cleaned Data'!V35) -> 8 | X35: 2 | Y35: =IFERROR('Cleaned Data'!R35/'Cleaned Data'!L35,0) -> 103129.39 | Z35: =TEXT(EV_Sales[[#This Row],[Order_Date]],"mmm-yyyy") -> Jan-2025 | AA35: =MONTH(EV_Sales[[#This Row],[Order_Date]]) -> 1 | AB35: ="Q"&ROUNDUP(MONTH(EV_Sales[[#This Row],[Order_Date]])/3,0) -> Q1
A36: EV10035 | B36: 45839 | C36: Hero Electric | D36: Photon | E36: Performance | F36: Jaipur | G36: Corporate | H36: Cash | I36: =IF('Cleaned Data'!H36="Emi","EMI",'Cleaned Data'!H36) -> Cash | J36: Blue | K36: SP-013 | L36: 2 | M36: 112104 | N36: 0.053 | O36: =IF(TRIM(N36&"")="","missing",N36) -> 0.053 | P36: 224208 | Q36: 11883.02 | R36: 212324.98 | S36: 3 | T36: 157 | U36: 3.4 | V36: 11 | W36: =IF('Cleaned Data'!V36<0,"Review",'Cleaned Data'!V36) -> 11 | X36: 2 | Y36: =IFERROR('Cleaned Data'!R36/'Cleaned Data'!L36,0) -> 106162.49 | Z36: =TEXT(EV_Sales[[#This Row],[Order_Date]],"mmm-yyyy") -> Jul-2025 | AA36: =MONTH(EV_Sales[[#This Row],[Order_Date]]) -> 7 | AB36: ="Q"&ROUNDUP(MONTH(EV_Sales[[#This Row],[Order_Date]])/3,0) -> Q3
... A97: EV10096 | B97: 46001 | C97: Hero Electric | D97: Optima | E97: Commuter | F97: Jaipur | G97: Dealer | H97: Finance | I97: =IF('Cleaned Data'!H97="Emi","EMI",'Cleaned Data'!H97) -> Finance | J97: Black | K97: SP-008 | L97: 1 | M97: 113169 | N97: 0.035 | O97: =IF(TRIM(N97&"")="","missing",N97) -> 0.035 | P97: 113169 | Q97: 3960.92 | R97: 109208.08 | S97: 3 | T97: 152 | U97: 4.8 | V97: 7 | W97: =IF('Cleaned Data'!V97<0,"Review",'Cleaned Data'!V97) -> 7 | X97: 5 | Y97: =IFERROR('Cleaned Data'!R97/'Cleaned Data'!L97,0) -> 109208.08 | Z97: =TEXT(EV_Sales[[#This Row],[Order_Date]],"mmm-yyyy") -> Dec-2025 | AA97: =MONTH(EV_Sales[[#This Row],[Order_Date]]) -> 12 | AB97: ="Q"&ROUNDUP(MONTH(EV_Sales[[#This Row],[Order_Date]])/3,0) -> Q4
A98: EV10097 | B98: 45836 | C98: TVS | D98: X | E98: Premium | F98: Ahmedabad | G98: Fleet | H98: Finance | I98: =IF('Cleaned Data'!H98="Emi","EMI",'Cleaned Data'!H98) -> Finance | J98: Red | K98: SP-001 | L98: 1 | M98: 175299 | N98: 0.119 | O98: =IF(TRIM(N98&"")="","missing",N98) -> 0.119 | P98: 175299 | Q98: 20860.58 | R98: 154438.42 | S98: 3 | T98: 192 | U98: Missing | V98: 5 | W98: =IF('Cleaned Data'!V98<0,"Review",'Cleaned Data'!V98) -> 5 | X98: 2 | Y98: =IFERROR('Cleaned Data'!R98/'Cleaned Data'!L98,0) -> 154438.42 | Z98: =TEXT(EV_Sales[[#This Row],[Order_Date]],"mmm-yyyy") -> Jun-2025 | AA98: =MONTH(EV_Sales[[#This Row],[Order_Date]]) -> 6 | AB98: ="Q"&ROUNDUP(MONTH(EV_Sales[[#This Row],[Order_Date]])/3,0) -> Q2
A99: EV10098 | B99: 45946 | C99: ola electric | D99: S1 Pro | E99: Performance | F99: Delhi | G99: Fleet | H99: Emi | I99: =IF('Cleaned Data'!H99="Emi","EMI",'Cleaned Data'!H99) -> EMI | J99: Grey | K99: SP-003 | L99: 4 | M99: 133217 | N99: 0.102 | O99: =IF(TRIM(N99&"")="","missing",N99) -> 0.102 | P99: 532868 | Q99: 54352.54 | R99: 478515.46 | S99: 3 | T99: 171 | U99: 3.7 | V99: 3 | W99: =IF('Cleaned Data'!V99<0,"Review",'Cleaned Data'!V99) -> 3 | X99: 3 | Y99: =IFERROR('Cleaned Data'!R99/'Cleaned Data'!L99,0) -> 119628.87 | Z99: =TEXT(EV_Sales[[#This Row],[Order_Date]],"mmm-yyyy") -> Oct-2025 | AA99: =MONTH(EV_Sales[[#This Row],[Order_Date]]) -> 10 | AB99: ="Q"&ROUNDUP(MONTH(EV_Sales[[#This Row],[Order_Date]])/3,0) -> Q4
A100: EV10099 | B100: 45666 | C100: TVS | D100: X | E100: Performance | F100: Kolkata | G100: Corporate | H100: Finance | I100: =IF('Cleaned Data'!H100="Emi","EMI",'Cleaned Data'!H100) -> Finance | J100: White | K100: SP-022 | L100: 5 | M100: 170509 | N100: 0.074 | O100: =IF(TRIM(N100&"")="","missing",N100) -> 0.074 | P100: 852545 | Q100: 63088.33 | R100: 789456.67 | S100: 4 | T100: 186 | U100: 4.4 | V100: 5 | W100: =IF('Cleaned Data'!V100<0,"Review",'Cleaned Data'!V100) -> 5 | X100: 3 | Y100: =IFERROR('Cleaned Data'!R100/'Cleaned Data'!L100,0) -> 157891.33 | Z100: =TEXT(EV_Sales[[#This Row],[Order_Date]],"mmm-yyyy") -> Jan-2025 | AA100: =MONTH(EV_Sales[[#This Row],[Order_Date]]) -> 1 | AB100: ="Q"&ROUNDUP(MONTH(EV_Sales[[#This Row],[Order_Date]])/3,0) -> Q1
A101: EV10100 | B101: 45660 | C101: Ola Electric | D101: S1 X | E101: Performance | F101: Kochi | G101: Corporate | H101: Emi | I101: =IF('Cleaned Data'!H101="Emi","EMI",'Cleaned Data'!H101) -> EMI | J101: Green | K101: SP-004 | L101: 1 | M101: 101110 | N101: 0.064 | O101: =IF(TRIM(N101&"")="","missing",N101) -> 0.064 | P101: 101110 | Q101: 6471.04 | R101: 94638.96 | S101: 4 | T101: 202 | U101: 4.6 | V101: 10 | W101: =IF('Cleaned Data'!V101<0,"Review",'Cleaned Data'!V101) -> 10 | X101: 2 | Y101: =IFERROR('Cleaned Data'!R101/'Cleaned Data'!L101,0) -> 94638.96 | Z101: =TEXT(EV_Sales[[#This Row],[Order_Date]],"mmm-yyyy") -> Jan-2025 | AA101: =MONTH(EV_Sales[[#This Row],[Order_Date]]) -> 1 | AB101: ="Q"&ROUNDUP(MONTH(EV_Sales[[#This Row],[Order_Date]])/3,0) -> Q1
A102: EV10101 | B102: 45878 | C102: Hero Electric | D102: Photon | E102: Performance | F102: Bengaluru | G102: Fleet | H102: Finance | I102: =IF('Cleaned Data'!H102="Emi","EMI",'Cleaned Data'!H102) -> Finance | J102: Blue | K102: SP-003 | L102: 3 | M102: 118705 | N102: 0.07 | O102: =IF(TRIM(N102&"")="","missing",N102) -> 0.07 | P102: 356115 | Q102: 24928.05 | R102: 331186.95 | S102: 4 | T102: 170 | U102: 4.4 | V102: 9 | W102: =IF('Cleaned Data'!V102<0,"Review",'Cleaned Data'!V102) -> 9 | X102: 2 | Y102: =IFERROR('Cleaned Data'!R102/'Cleaned Data'!L102,0) -> 110395.65 | Z102: =TEXT(EV_Sales[[#This Row],[Order_Date]],"mmm-yyyy") -> Aug-2025 | AA102: =MONTH(EV_Sales[[#This Row],[Order_Date]]) -> 8 | AB102: ="Q"&ROUNDUP(MONTH(EV_Sales[[#This Row],[Order_Date]])/3,0) -> Q3
A103: EV10102 | B103: 45864 | C103: Hero Electric | D103: Optima | E103: Premium | F103: Delhi | G103: Corporate | H103: Cash | I103: =IF('Cleaned Data'!H103="Emi","EMI",'Cleaned Data'!H103) -> Cash | J103: Red | K103: SP-026 | L103: 1 | M103: 105500 | N103: 0.107 | O103: =IF(TRIM(N103&"")="","missing",N103) -> 0.107 | P103: 105500 | Q103: 11288.5 | R103: 94211.5 | S103: 4 | T103: 176 | U103: 4.8 | V103: 5 | W103: =IF('Cleaned Data'!V103<0,"Review",'Cleaned Data'!V103) -> 5 | X103: 3 | Y103: =IFERROR('Cleaned Data'!R103/'Cleaned Data'!L103,0) -> 94211.5 | Z103: =TEXT(EV_Sales[[#This Row],[Order_Date]],"mmm-yyyy") -> Jul-2025 | AA103: =MONTH(EV_Sales[[#This Row],[Order_Date]]) -> 7 | AB103: ="Q"&ROUNDUP(MONTH(EV_Sales[[#This Row],[Order_Date]])/3,0) -> Q3
A104: EV10103 | B104: 45885 | C104: Hero Electric | D104: Photon | E104: Commuter | F104: Mumbai | G104: Fleet | H104: Cash | I104: =IF('Cleaned Data'!H104="Emi","EMI",'Cleaned Data'!H104) -> Cash | J104: Black | K104: SP-003 | L104: 4 | M104: 122601 | N104: 0.062 | O104: =IF(TRIM(N104&"")="","missing",N104) -> 0.062 | P104: 490404 | Q104: 30405.05 | R104: 459998.95 | S104: 3 | T104: 173 | U104: 4.2 | V104: 13 | W104: =IF('Cleaned Data'!V104<0,"Review",'Cleaned Data'!V104) -> 13 | X104: 5 | Y104: =IFERROR('Cleaned Data'!R104/'Cleaned Data'!L104,0) -> 114999.74 | Z104: =TEXT(EV_Sales[[#This Row],[Order_Date]],"mmm-yyyy") -> Aug-2025 | AA104: =MONTH(EV_Sales[[#This Row],[Order_Date]]) -> 8 | AB104: ="Q"&ROUNDUP(MONTH(EV_Sales[[#This Row],[Order_Date]])/3,0) -> Q3
A105: EV10104 | B105: 45744 | C105: Ola Electric | D105: S1 Air | E105: Performance | F105: Ahmedabad | G105: Corporate | H105: Cash | I105: =IF('Cleaned Data'!H105="Emi","EMI",'Cleaned Data'!H105) -> Cash | J105: Red | K105: SP-002 | L105: 2 | M105: 114102 | N105: 0.071 | O105: =IF(TRIM(N105&"")="","missing",N105) -> 0.071 | P105: 228204 | Q105: 16202.48 | R105: 212001.52 | S105: 3 | T105: 162 | U105: 3.8 | V105: 7 | W105: =IF('Cleaned Data'!V105<0,"Review",'Cleaned Data'!V105) -> 7 | X105: 2 | Y105: =IFERROR('Cleaned Data'!R105/'Cleaned Data'!L105,0) -> 106000.76 | Z105: =TEXT(EV_Sales[[#This Row],[Order_Date]],"mmm-yyyy") -> Mar-2025 | AA105: =MONTH(EV_Sales[[#This Row],[Order_Date]]) -> 3 | AB105: ="Q"&ROUNDUP(MONTH(EV_Sales[[#This Row],[Order_Date]])/3,0) -> Q1
A106: EV10105 | B106: 45802 | C106: Revolt | D106: RV1 | E106: Performance | F106: Kochi | G106: Corporate | H106: Finance | I106: =IF('Cleaned Data'!H106="Emi","EMI",'Cleaned Data'!H106) -> Finance | J106: Green | K106: SP-016 | L106: 1 | M106: 129086 | N106: 0.046 | O106: =IF(TRIM(N106&"")="","missing",N106) -> 0.046 | P106: 129086 | Q106: 5937.96 | R106: 123148.04 | S106: 4 | T106: 195 | U106: 3.8 | V106: 9 | W106: =IF('Cleaned Data'!V106<0,"Review",'Cleaned Data'!V106) -> 9 | X106: 2 | Y106: =IFERROR('Cleaned Data'!R106/'Cleaned Data'!L106,0) -> 123148.04 | Z106: =TEXT(EV_Sales[[#This Row],[Order_Date]],"mmm-yyyy") -> May-2025 | AA106: =MONTH(EV_Sales[[#This Row],[Order_Date]]) -> 5 | AB106: ="Q"&ROUNDUP(MONTH(EV_Sales[[#This Row],[Order_Date]])/3,0) -> Q2
A107: EV10106 | B107: 45923 | C107: Ola Electric | D107: S1 Pro | E107: Performance | F107: Chennai | G107: Fleet | H107: Cash | I107: =IF('Cleaned Data'!H107="Emi","EMI",'Cleaned Data'!H107) -> Cash | J107: Black | K107: SP-017 | L107: 2 | M107: 134456 | N107: 0.065 | O107: =IF(TRIM(N107&"")="","missing",N107) -> 0.065 | P107: 268912 | Q107: 17479.28 | R107: 251432.72 | S107: 4 | T107: 166 | U107: 3.4 | V107: 12 | W107: =IF('Cleaned Data'!V107<0,"Review",'Cleaned Data'!V107) -> 12 | X107: 2 | Y107: =IFERROR('Cleaned Data'!R107/'Cleaned Data'!L107,0) -> 125716.36 | Z107: =TEXT(EV_Sales[[#This Row],[Order_Date]],"mmm-yyyy") -> Sep-2025 | AA107: =MONTH(EV_Sales[[#This Row],[Order_Date]]) -> 9 | AB107: ="Q"&ROUNDUP(MONTH(EV_Sales[[#This Row],[Order_Date]])/3,0) -> Q3
A108: EV10107 | B108: 45969 | C108: Vida | D108: V2 | E108: Commuter | F108: Delhi | G108: Corporate | H108: Emi | I108: =IF('Cleaned Data'!H108="Emi","EMI",'Cleaned Data'!H108) -> EMI | J108: Green | K108: SP-005 | L108: 2 | M108: 116771 | N108: 0.041 | O108: =IF(TRIM(N108&"")="","missing",N108) -> 0.041 | P108: 233542 | Q108: 9575.22 | R108: 223966.78 | S108: 2 | T108: 145 | U108: 4.1 | V108: 6 | W108: =IF('Cleaned Data'!V108<0,"Review",'Cleaned Data'!V108) -> 6 | X108: 3 | Y108: =IFERROR('Cleaned Data'!R108/'Cleaned Data'!L108,0) -> 111983.39 | Z108: =TEXT(EV_Sales[[#This Row],[Order_Date]],"mmm-yyyy") -> Nov-2025 | AA108: =MONTH(EV_Sales[[#This Row],[Order_Date]]) -> 11 | AB108: ="Q"&ROUNDUP(MONTH(EV_Sales[[#This Row],[Order_Date]])/3,0) -> Q4
A109: EV10108 | B109: 45982 | C109: Hero Electric | D109: Optima | E109: Premium | F109: Jaipur | G109: Corporate | H109: Emi | I109: =IF('Cleaned Data'!H109="Emi","EMI",'Cleaned Data'!H109) -> EMI | J109: Blue | K109: SP-018 | L109: 1 | M109: 107294 | N109: 0.089 | O109: =IF(TRIM(N109&"")="","missing",N109) -> 0.089 | P109: 107294 | Q109: 9549.17 | R109: 97744.83 | S109: 3 | T109: 187 | U109: 4 | V109: 3 | W109: =IF('Cleaned Data'!V109<0,"Review",'Cleaned Data'!V109) -> 3 | X109: 2 | Y109: =IFERROR('Cleaned Data'!R109/'Cleaned Data'!L109,0) -> 97744.83 | Z109: =TEXT(EV_Sales[[#This Row],[Order_Date]],"mmm-yyyy") -> Nov-2025 | AA109: =MONTH(EV_Sales[[#This Row],[Order_Date]]) -> 11 | AB109: ="Q"&ROUNDUP(MONTH(EV_Sales[[#This Row],[Order_Date]])/3,0) -> Q4
...

Sheet Pivot_Salesperson_Performance
A3: Row Labels | B3: Average of Customer_Rating | C3: Sum of Units_Sold | D3: Sum of Net_Sales
A4: SP-001 | B4: 4.1608696 | C4: 48 | D4: 5672955.4
A5: SP-002 | B5: 4.0826087 | C5: 37 | D5: 4218781.6
A6: SP-003 | B6: 4.0242424 | C6: 85 | D6: 10541686
A7: SP-004 | B7: 4.1590909 | C7: 46 | D7: 5399908.5
A8: SP-005 | B8: 4.2095238 | C8: 38 | D8: 4769021.2
A9: SP-006 | B9: 4.0117647 | C9: 28 | D9: 3478279.1
A10: SP-007 | B10: 3.8833333 | C10: 48 | D10: 5755963.1
A11: SP-008 | B11: 4.09375 | C11: 35 | D11: 4064335.5
A12: SP-009 | B12: 4.1095238 | C12: 43 | D12: 5450994.6
A13: SP-010 | B13: 4.2181818 | C13: 41 | D13: 5023702.3
A14: SP-011 | B14: 4.137931 | C14: 62 | D14: 7432691.6
A15: SP-012 | B15: 3.9038462 | C15: 54 | D15: 6479835.7
... A34: Grand Total | B34: 4.0982684 | C34: 1394 | D34: 1.700259e+08

Sheet Pivot_Channel_Performance
A3: Row Labels | B3: Sum of Net_Sales | C3: Sum of Units_Sold
A4: Corporate | B4: 44041221 | C4: 358
A5: Dealer | B5: 43145751 | C5: 352
A6: Fleet | B6: 41899592 | C6: 344
A7: Online | B7: 40939334 | C7: 340
A8: Grand Total | B8: 1.700259e+08 | C8: 1394

Sheet Pivot_Segment _Performance
A3: Row Labels | B3: Sum of Units_Sold
A4: Ampere | B4: 194
A5: Magnus EX | B5: 99
A6: Commuter | B6: 33
A7: Performance | B7: 36
A8: Premium | B8: 30
A9: Primus | B9: 95
A10: Commuter | B10: 31
A11: Performance | B11: 22
A12: Premium | B12: 42
A13: Ather | B13: 176
A14: 450S | B14: 65
A15: Commuter | B15: 20
... A84: Grand Total | B84: 1394

Sheet Pivot_Brand_Performance
A3: Row Labels | B3: Sum of Net_Sales | C3: Sum of Units_Sold
A4: Ampere | B4: 23523906 | C4: 194
A5: Magnus EX | B5: 10213368 | C5: 99
A6: Primus | B6: 13310538 | C6: 95
A7: Ather | B7: 22544869 | C7: 176
A8: 450S | B8: 7832619.8 | C8: 65
A9: 450X | B9: 7265587.6 | C9: 54
A10: Rizta | B10: 7446661.3 | C10: 57
A11: Bajaj | B11: 23636039 | C11: 187
A12: Chetak Premium | B12: 11208690 | C12: 79
A13: Chetak Urbane | B13: 12427349 | C13: 108
A14: Hero Electric | B14: 19049824 | C14: 183
A15: Optima | B15: 7837630.2 | C15: 80
... A30: Grand Total | B30: 1.700259e+08 | C30: 1394

Sheet Pivot_Montly_Sales
A3: Row Labels | B3: Sum of Units_Sold | C3: Sum of Net_Sales
A4: Q1 | B4: 333 | C4: 41560702
A5: 1 | B5: 128 | C5: 15726717
A6: 2 | B6: 95 | C6: 11750041
A7: 3 | B7: 110 | C7: 14083944
A8: Q2 | B8: 371 | C8: 45123934
A9: 4 | B9: 131 | C9: 15423248
A10: 5 | B10: 103 | C10: 12742849
A11: 6 | B11: 137 | C11: 16957837
A12: Q3 | B12: 330 | C12: 39755768
A13: 7 | B13: 99 | C13: 11327894
A14: 8 | B14: 123 | C14: 14864722
A15: 9 | B15: 108 | C15: 13563151
A16: Q4 | B16: 360 | C16: 43585495
A17: 10 | B17: 120 | C17: 14314723
A18: 11 | B18: 120 | C18: 15382833
A19: 12 | B19: 120 | C19: 13887939
A20: Grand Total | B20: 1394 | C20: 1.700259e+08

Sheet DASHBOARD
A1: =SUM(EV_Sales[Net_Sales]) -> 1.700259e+08
A3: =SUM(EV_Sales[Units_Sold]) -> 1394
A5: =COUNTA(EV_Sales[Order_ID]) -> 700
A7: =AVERAGE(EV_Sales[ASP]) -> 121603.07
A9: =AVERAGE(EV_Sales[Customer_Rating]) -> 4.0982684
A11: =AVERAGE(EV_Sales[Delivery_Days]) -> 7.8657143
